[2025-10-20T16:46:21.575+0300] {local_task_job_runner.py:120} INFO - ::group::Pre task execution logs
[2025-10-20T16:46:35.654+0300] {taskinstance.py:2076} INFO - Dependencies all met for dep_context=non-requeueable deps ti=<TaskInstance: stock_etl.extract_NVDA manual__2025-10-20T13:45:40+00:00 [queued]>
[2025-10-20T16:46:39.291+0300] {taskinstance.py:2076} INFO - Dependencies all met for dep_context=requeueable deps ti=<TaskInstance: stock_etl.extract_NVDA manual__2025-10-20T13:45:40+00:00 [queued]>
[2025-10-20T16:46:39.292+0300] {taskinstance.py:2306} INFO - Starting attempt 1 of 2
[2025-10-20T16:46:43.370+0300] {taskinstance.py:2330} INFO - Executing <Task(PythonOperator): extract_NVDA> on 2025-10-20 13:45:40+00:00
[2025-10-20T16:46:44.133+0300] {logging_mixin.py:188} WARNING - /home/airflow/.local/lib/python3.12/site-packages/airflow/task/task_runner/standard_task_runner.py:62 DeprecationWarning: This process (pid=200) is multi-threaded, use of fork() may lead to deadlocks in the child.
[2025-10-20T16:46:43.826+0300] {standard_task_runner.py:90} INFO - Running: ['airflow', 'tasks', 'run', 'stock_etl', 'extract_NVDA', 'manual__2025-10-20T13:45:40+00:00', '--job-id', '41', '--raw', '--subdir', 'DAGS_FOLDER/stock_etl_dag.py', '--cfg-path', '/tmp/tmp3o5glg6w']
[2025-10-20T16:46:44.140+0300] {standard_task_runner.py:64} INFO - Started process 214 to run task
[2025-10-20T16:46:44.140+0300] {standard_task_runner.py:91} INFO - Job 41: Subtask extract_NVDA
[2025-10-20T16:47:00.094+0300] {task_command.py:426} INFO - Running <TaskInstance: stock_etl.extract_NVDA manual__2025-10-20T13:45:40+00:00 [running]> on host 51be0a441cbc
[2025-10-20T16:47:33.190+0300] {taskinstance.py:2648} INFO - Exporting env vars: AIRFLOW_CTX_DAG_OWNER='airflow' AIRFLOW_CTX_DAG_ID='stock_etl' AIRFLOW_CTX_TASK_ID='extract_NVDA' AIRFLOW_CTX_EXECUTION_DATE='2025-10-20T13:45:40+00:00' AIRFLOW_CTX_TRY_NUMBER='1' AIRFLOW_CTX_DAG_RUN_ID='manual__2025-10-20T13:45:40+00:00'
[2025-10-20T16:47:33.193+0300] {taskinstance.py:430} INFO - ::endgroup::
[2025-10-20T16:47:48.120+0300] {taskinstance.py:441} INFO - ::group::Post task execution logs
[2025-10-20T16:47:48.122+0300] {taskinstance.py:2905} ERROR - Task failed with exception
Traceback (most recent call last):
  File "/home/airflow/.local/lib/python3.12/site-packages/urllib3/connectionpool.py", line 791, in urlopen
    response = self._make_request(
               ^^^^^^^^^^^^^^^^^^^
  File "/home/airflow/.local/lib/python3.12/site-packages/urllib3/connectionpool.py", line 537, in _make_request
    response = conn.getresponse()
               ^^^^^^^^^^^^^^^^^^
  File "/home/airflow/.local/lib/python3.12/site-packages/urllib3/connection.py", line 461, in getresponse
    httplib_response = super().getresponse()
                       ^^^^^^^^^^^^^^^^^^^^^
  File "/usr/local/lib/python3.12/http/client.py", line 1428, in getresponse
    response.begin()
  File "/usr/local/lib/python3.12/http/client.py", line 331, in begin
    version, status, reason = self._read_status()
                              ^^^^^^^^^^^^^^^^^^^
  File "/usr/local/lib/python3.12/http/client.py", line 300, in _read_status
    raise RemoteDisconnected("Remote end closed connection without"
http.client.RemoteDisconnected: Remote end closed connection without response

During handling of the above exception, another exception occurred:

Traceback (most recent call last):
  File "/home/airflow/.local/lib/python3.12/site-packages/requests/adapters.py", line 667, in send
    resp = conn.urlopen(
           ^^^^^^^^^^^^^
  File "/home/airflow/.local/lib/python3.12/site-packages/urllib3/connectionpool.py", line 845, in urlopen
    retries = retries.increment(
              ^^^^^^^^^^^^^^^^^^
  File "/home/airflow/.local/lib/python3.12/site-packages/urllib3/util/retry.py", line 470, in increment
    raise reraise(type(error), error, _stacktrace)
          ^^^^^^^^^^^^^^^^^^^^^^^^^^^^^^^^^^^^^^^^
  File "/home/airflow/.local/lib/python3.12/site-packages/urllib3/util/util.py", line 38, in reraise
    raise value.with_traceback(tb)
  File "/home/airflow/.local/lib/python3.12/site-packages/urllib3/connectionpool.py", line 791, in urlopen
    response = self._make_request(
               ^^^^^^^^^^^^^^^^^^^
  File "/home/airflow/.local/lib/python3.12/site-packages/urllib3/connectionpool.py", line 537, in _make_request
    response = conn.getresponse()
               ^^^^^^^^^^^^^^^^^^
  File "/home/airflow/.local/lib/python3.12/site-packages/urllib3/connection.py", line 461, in getresponse
    httplib_response = super().getresponse()
                       ^^^^^^^^^^^^^^^^^^^^^
  File "/usr/local/lib/python3.12/http/client.py", line 1428, in getresponse
    response.begin()
  File "/usr/local/lib/python3.12/http/client.py", line 331, in begin
    version, status, reason = self._read_status()
                              ^^^^^^^^^^^^^^^^^^^
  File "/usr/local/lib/python3.12/http/client.py", line 300, in _read_status
    raise RemoteDisconnected("Remote end closed connection without"
urllib3.exceptions.ProtocolError: ('Connection aborted.', RemoteDisconnected('Remote end closed connection without response'))

During handling of the above exception, another exception occurred:

Traceback (most recent call last):
  File "/home/airflow/.local/lib/python3.12/site-packages/airflow/models/taskinstance.py", line 465, in _execute_task
    result = _execute_callable(context=context, **execute_callable_kwargs)
             ^^^^^^^^^^^^^^^^^^^^^^^^^^^^^^^^^^^^^^^^^^^^^^^^^^^^^^^^^^^^^
  File "/home/airflow/.local/lib/python3.12/site-packages/airflow/models/taskinstance.py", line 432, in _execute_callable
    return execute_callable(context=context, **execute_callable_kwargs)
           ^^^^^^^^^^^^^^^^^^^^^^^^^^^^^^^^^^^^^^^^^^^^^^^^^^^^^^^^^^^^
  File "/home/airflow/.local/lib/python3.12/site-packages/airflow/models/baseoperator.py", line 401, in wrapper
    return func(self, *args, **kwargs)
           ^^^^^^^^^^^^^^^^^^^^^^^^^^^
  File "/home/airflow/.local/lib/python3.12/site-packages/airflow/operators/python.py", line 235, in execute
    return_value = self.execute_callable()
                   ^^^^^^^^^^^^^^^^^^^^^^^
  File "/home/airflow/.local/lib/python3.12/site-packages/airflow/operators/python.py", line 252, in execute_callable
    return self.python_callable(*self.op_args, **self.op_kwargs)
           ^^^^^^^^^^^^^^^^^^^^^^^^^^^^^^^^^^^^^^^^^^^^^^^^^^^^^
  File "/opt/airflow/dags/stock_etl_dag.py", line 37, in extract_data
    response = requests.get(url)
               ^^^^^^^^^^^^^^^^^
  File "/home/airflow/.local/lib/python3.12/site-packages/requests/api.py", line 73, in get
    return request("get", url, params=params, **kwargs)
           ^^^^^^^^^^^^^^^^^^^^^^^^^^^^^^^^^^^^^^^^^^^^
  File "/home/airflow/.local/lib/python3.12/site-packages/requests/api.py", line 59, in request
    return session.request(method=method, url=url, **kwargs)
           ^^^^^^^^^^^^^^^^^^^^^^^^^^^^^^^^^^^^^^^^^^^^^^^^^
  File "/home/airflow/.local/lib/python3.12/site-packages/requests/sessions.py", line 589, in request
    resp = self.send(prep, **send_kwargs)
           ^^^^^^^^^^^^^^^^^^^^^^^^^^^^^^
  File "/home/airflow/.local/lib/python3.12/site-packages/requests/sessions.py", line 703, in send
    r = adapter.send(request, **kwargs)
        ^^^^^^^^^^^^^^^^^^^^^^^^^^^^^^^
  File "/home/airflow/.local/lib/python3.12/site-packages/requests/adapters.py", line 682, in send
    raise ConnectionError(err, request=request)
requests.exceptions.ConnectionError: ('Connection aborted.', RemoteDisconnected('Remote end closed connection without response'))
[2025-10-20T16:47:54.535+0300] {taskinstance.py:1206} INFO - Marking task as UP_FOR_RETRY. dag_id=stock_etl, task_id=extract_NVDA, run_id=manual__2025-10-20T13:45:40+00:00, execution_date=20251020T134540, start_date=20251020T134635, end_date=20251020T134754
[2025-10-20T16:47:57.563+0300] {standard_task_runner.py:110} ERROR - Failed to execute job 41 for task extract_NVDA (('Connection aborted.', RemoteDisconnected('Remote end closed connection without response')); 214)
[2025-10-20T16:47:57.596+0300] {local_task_job_runner.py:243} INFO - Task exited with return code 1
[2025-10-20T16:48:02.039+0300] {taskinstance.py:3503} INFO - 0 downstream tasks scheduled from follow-on schedule check
[2025-10-20T16:48:02.293+0300] {local_task_job_runner.py:222} INFO - ::endgroup::
