[2025-10-21T01:36:29.051+0300] {local_task_job_runner.py:120} INFO - ::group::Pre task execution logs
[2025-10-21T01:36:32.745+0300] {taskinstance.py:2076} INFO - Dependencies all met for dep_context=non-requeueable deps ti=<TaskInstance: stock_etl.load_task manual__2025-10-20T22:31:28.253460+00:00 [queued]>
[2025-10-21T01:36:34.313+0300] {taskinstance.py:2076} INFO - Dependencies all met for dep_context=requeueable deps ti=<TaskInstance: stock_etl.load_task manual__2025-10-20T22:31:28.253460+00:00 [queued]>
[2025-10-21T01:36:34.315+0300] {taskinstance.py:2306} INFO - Starting attempt 1 of 4
[2025-10-21T01:36:36.291+0300] {taskinstance.py:2330} INFO - Executing <Task(PythonOperator): load_task> on 2025-10-20 22:31:28.253460+00:00
[2025-10-21T01:36:36.335+0300] {standard_task_runner.py:90} INFO - Running: ['airflow', 'tasks', 'run', 'stock_etl', 'load_task', 'manual__2025-10-20T22:31:28.253460+00:00', '--job-id', '124', '--raw', '--subdir', 'DAGS_FOLDER/stock_etl_dag.py', '--cfg-path', '/tmp/tmp7hq6p7ic']
[2025-10-21T01:36:36.353+0300] {standard_task_runner.py:91} INFO - Job 124: Subtask load_task
[2025-10-21T01:36:36.381+0300] {logging_mixin.py:188} WARNING - /home/airflow/.local/lib/python3.12/site-packages/airflow/task/task_runner/standard_task_runner.py:62 DeprecationWarning: This process (pid=274) is multi-threaded, use of fork() may lead to deadlocks in the child.
[2025-10-21T01:36:36.386+0300] {standard_task_runner.py:64} INFO - Started process 282 to run task
[2025-10-21T01:36:47.948+0300] {task_command.py:426} INFO - Running <TaskInstance: stock_etl.load_task manual__2025-10-20T22:31:28.253460+00:00 [running]> on host d02b2e7b696f
[2025-10-21T01:37:00.988+0300] {taskinstance.py:2648} INFO - Exporting env vars: AIRFLOW_CTX_DAG_OWNER='airflow' AIRFLOW_CTX_DAG_ID='stock_etl' AIRFLOW_CTX_TASK_ID='load_task' AIRFLOW_CTX_EXECUTION_DATE='2025-10-20T22:31:28.253460+00:00' AIRFLOW_CTX_TRY_NUMBER='1' AIRFLOW_CTX_DAG_RUN_ID='manual__2025-10-20T22:31:28.253460+00:00'
[2025-10-21T01:37:00.996+0300] {taskinstance.py:430} INFO - ::endgroup::
[2025-10-21T01:37:05.521+0300] {logging_mixin.py:188} WARNING - /opt/airflow/dags/stock_etl_dag.py:70 FutureWarning: Passing literal json to 'read_json' is deprecated and will be removed in a future version. To read from a literal string, wrap it in a 'StringIO' object.
[2025-10-21T01:37:11.007+0300] {taskinstance.py:441} INFO - ::group::Post task execution logs
[2025-10-21T01:37:11.011+0300] {taskinstance.py:2905} ERROR - Task failed with exception
Traceback (most recent call last):
  File "/home/airflow/.local/lib/python3.12/site-packages/sqlalchemy/engine/base.py", line 1910, in _execute_context
    self.dialect.do_execute(
  File "/home/airflow/.local/lib/python3.12/site-packages/sqlalchemy/engine/default.py", line 736, in do_execute
    cursor.execute(statement, parameters)
psycopg2.errors.UndefinedColumn: column "ticker" does not exist
LINE 3:             SELECT ticker, timestamp, open, high, low, close...
                           ^
DETAIL:  There is a column named "ticker" in table "stock_data", but it cannot be referenced from this part of the query.


The above exception was the direct cause of the following exception:

Traceback (most recent call last):
  File "/home/airflow/.local/lib/python3.12/site-packages/airflow/models/taskinstance.py", line 465, in _execute_task
    result = _execute_callable(context=context, **execute_callable_kwargs)
             ^^^^^^^^^^^^^^^^^^^^^^^^^^^^^^^^^^^^^^^^^^^^^^^^^^^^^^^^^^^^^
  File "/home/airflow/.local/lib/python3.12/site-packages/airflow/models/taskinstance.py", line 432, in _execute_callable
    return execute_callable(context=context, **execute_callable_kwargs)
           ^^^^^^^^^^^^^^^^^^^^^^^^^^^^^^^^^^^^^^^^^^^^^^^^^^^^^^^^^^^^
  File "/home/airflow/.local/lib/python3.12/site-packages/airflow/models/baseoperator.py", line 401, in wrapper
    return func(self, *args, **kwargs)
           ^^^^^^^^^^^^^^^^^^^^^^^^^^^
  File "/home/airflow/.local/lib/python3.12/site-packages/airflow/operators/python.py", line 235, in execute
    return_value = self.execute_callable()
                   ^^^^^^^^^^^^^^^^^^^^^^^
  File "/home/airflow/.local/lib/python3.12/site-packages/airflow/operators/python.py", line 252, in execute_callable
    return self.python_callable(*self.op_args, **self.op_kwargs)
           ^^^^^^^^^^^^^^^^^^^^^^^^^^^^^^^^^^^^^^^^^^^^^^^^^^^^^
  File "/opt/airflow/dags/stock_etl_dag.py", line 92, in load_data
    conn.execute(text(f"""
  File "/home/airflow/.local/lib/python3.12/site-packages/sqlalchemy/engine/base.py", line 1385, in execute
    return meth(self, multiparams, params, _EMPTY_EXECUTION_OPTS)
           ^^^^^^^^^^^^^^^^^^^^^^^^^^^^^^^^^^^^^^^^^^^^^^^^^^^^^^
  File "/home/airflow/.local/lib/python3.12/site-packages/sqlalchemy/sql/elements.py", line 334, in _execute_on_connection
    return connection._execute_clauseelement(
           ^^^^^^^^^^^^^^^^^^^^^^^^^^^^^^^^^^
  File "/home/airflow/.local/lib/python3.12/site-packages/sqlalchemy/engine/base.py", line 1577, in _execute_clauseelement
    ret = self._execute_context(
          ^^^^^^^^^^^^^^^^^^^^^^
  File "/home/airflow/.local/lib/python3.12/site-packages/sqlalchemy/engine/base.py", line 1953, in _execute_context
    self._handle_dbapi_exception(
  File "/home/airflow/.local/lib/python3.12/site-packages/sqlalchemy/engine/base.py", line 2134, in _handle_dbapi_exception
    util.raise_(
  File "/home/airflow/.local/lib/python3.12/site-packages/sqlalchemy/util/compat.py", line 211, in raise_
    raise exception
  File "/home/airflow/.local/lib/python3.12/site-packages/sqlalchemy/engine/base.py", line 1910, in _execute_context
    self.dialect.do_execute(
  File "/home/airflow/.local/lib/python3.12/site-packages/sqlalchemy/engine/default.py", line 736, in do_execute
    cursor.execute(statement, parameters)
sqlalchemy.exc.ProgrammingError: (psycopg2.errors.UndefinedColumn) column "ticker" does not exist
LINE 3:             SELECT ticker, timestamp, open, high, low, close...
                           ^
DETAIL:  There is a column named "ticker" in table "stock_data", but it cannot be referenced from this part of the query.

[SQL: 
            INSERT INTO stock_data (ticker, timestamp, open, high, low, close, volume)
            SELECT ticker, timestamp, open, high, low, close, volume
            FROM temp_stock_data
            ON CONFLICT (ticker, timestamp) DO NOTHING;
        ]
(Background on this error at: https://sqlalche.me/e/14/f405)
[2025-10-21T01:37:13.529+0300] {taskinstance.py:1206} INFO - Marking task as UP_FOR_RETRY. dag_id=stock_etl, task_id=load_task, run_id=manual__2025-10-20T22:31:28.253460+00:00, execution_date=20251020T223128, start_date=20251020T223632, end_date=20251020T223713
[2025-10-21T01:37:19.046+0300] {standard_task_runner.py:110} ERROR - Failed to execute job 124 for task load_task ((psycopg2.errors.UndefinedColumn) column "ticker" does not exist
LINE 3:             SELECT ticker, timestamp, open, high, low, close...
                           ^
DETAIL:  There is a column named "ticker" in table "stock_data", but it cannot be referenced from this part of the query.

[SQL: 
            INSERT INTO stock_data (ticker, timestamp, open, high, low, close, volume)
            SELECT ticker, timestamp, open, high, low, close, volume
            FROM temp_stock_data
            ON CONFLICT (ticker, timestamp) DO NOTHING;
        ]
(Background on this error at: https://sqlalche.me/e/14/f405); 282)
[2025-10-21T01:37:19.164+0300] {local_task_job_runner.py:243} INFO - Task exited with return code 1
[2025-10-21T01:37:22.717+0300] {taskinstance.py:3503} INFO - 0 downstream tasks scheduled from follow-on schedule check
[2025-10-21T01:37:23.104+0300] {local_task_job_runner.py:222} INFO - ::endgroup::
