[2025-10-21T01:16:48.238+0300] {local_task_job_runner.py:120} INFO - ::group::Pre task execution logs
[2025-10-21T01:16:51.732+0300] {taskinstance.py:2076} INFO - Dependencies all met for dep_context=non-requeueable deps ti=<TaskInstance: stock_etl.load_task manual__2025-10-20T22:07:02.645204+00:00 [queued]>
[2025-10-21T01:16:53.317+0300] {taskinstance.py:2076} INFO - Dependencies all met for dep_context=requeueable deps ti=<TaskInstance: stock_etl.load_task manual__2025-10-20T22:07:02.645204+00:00 [queued]>
[2025-10-21T01:16:53.559+0300] {taskinstance.py:2306} INFO - Starting attempt 2 of 4
[2025-10-21T01:16:55.500+0300] {taskinstance.py:2330} INFO - Executing <Task(PythonOperator): load_task> on 2025-10-20 22:07:02.645204+00:00
[2025-10-21T01:16:55.631+0300] {standard_task_runner.py:90} INFO - Running: ['airflow', 'tasks', 'run', 'stock_etl', 'load_task', 'manual__2025-10-20T22:07:02.645204+00:00', '--job-id', '118', '--raw', '--subdir', 'DAGS_FOLDER/stock_etl_dag.py', '--cfg-path', '/tmp/tmp4cxk382o']
[2025-10-21T01:16:55.634+0300] {standard_task_runner.py:91} INFO - Job 118: Subtask load_task
[2025-10-21T01:16:55.637+0300] {logging_mixin.py:188} WARNING - /home/airflow/.local/lib/python3.12/site-packages/airflow/task/task_runner/standard_task_runner.py:62 DeprecationWarning: This process (pid=322) is multi-threaded, use of fork() may lead to deadlocks in the child.
[2025-10-21T01:16:55.638+0300] {standard_task_runner.py:64} INFO - Started process 328 to run task
[2025-10-21T01:17:08.637+0300] {task_command.py:426} INFO - Running <TaskInstance: stock_etl.load_task manual__2025-10-20T22:07:02.645204+00:00 [running]> on host 2c343af78455
[2025-10-21T01:17:22.219+0300] {taskinstance.py:2648} INFO - Exporting env vars: AIRFLOW_CTX_DAG_OWNER='airflow' AIRFLOW_CTX_DAG_ID='stock_etl' AIRFLOW_CTX_TASK_ID='load_task' AIRFLOW_CTX_EXECUTION_DATE='2025-10-20T22:07:02.645204+00:00' AIRFLOW_CTX_TRY_NUMBER='2' AIRFLOW_CTX_DAG_RUN_ID='manual__2025-10-20T22:07:02.645204+00:00'
[2025-10-21T01:17:22.221+0300] {taskinstance.py:430} INFO - ::endgroup::
[2025-10-21T01:17:24.783+0300] {logging_mixin.py:188} WARNING - /opt/airflow/dags/stock_etl_dag.py:70 FutureWarning: Passing literal json to 'read_json' is deprecated and will be removed in a future version. To read from a literal string, wrap it in a 'StringIO' object.
[2025-10-21T01:17:37.310+0300] {taskinstance.py:441} INFO - ::group::Post task execution logs
[2025-10-21T01:17:37.310+0300] {taskinstance.py:2905} ERROR - Task failed with exception
Traceback (most recent call last):
  File "/home/airflow/.local/lib/python3.12/site-packages/sqlalchemy/engine/base.py", line 1910, in _execute_context
    self.dialect.do_execute(
  File "/home/airflow/.local/lib/python3.12/site-packages/sqlalchemy/engine/default.py", line 736, in do_execute
    cursor.execute(statement, parameters)
psycopg2.errors.UndefinedColumn: column t.ticker does not exist
LINE 3:             SELECT t.ticker, t.timestamp, t.open, t.high, t....
                           ^


The above exception was the direct cause of the following exception:

Traceback (most recent call last):
  File "/home/airflow/.local/lib/python3.12/site-packages/airflow/models/taskinstance.py", line 465, in _execute_task
    result = _execute_callable(context=context, **execute_callable_kwargs)
             ^^^^^^^^^^^^^^^^^^^^^^^^^^^^^^^^^^^^^^^^^^^^^^^^^^^^^^^^^^^^^
  File "/home/airflow/.local/lib/python3.12/site-packages/airflow/models/taskinstance.py", line 432, in _execute_callable
    return execute_callable(context=context, **execute_callable_kwargs)
           ^^^^^^^^^^^^^^^^^^^^^^^^^^^^^^^^^^^^^^^^^^^^^^^^^^^^^^^^^^^^
  File "/home/airflow/.local/lib/python3.12/site-packages/airflow/models/baseoperator.py", line 401, in wrapper
    return func(self, *args, **kwargs)
           ^^^^^^^^^^^^^^^^^^^^^^^^^^^
  File "/home/airflow/.local/lib/python3.12/site-packages/airflow/operators/python.py", line 235, in execute
    return_value = self.execute_callable()
                   ^^^^^^^^^^^^^^^^^^^^^^^
  File "/home/airflow/.local/lib/python3.12/site-packages/airflow/operators/python.py", line 252, in execute_callable
    return self.python_callable(*self.op_args, **self.op_kwargs)
           ^^^^^^^^^^^^^^^^^^^^^^^^^^^^^^^^^^^^^^^^^^^^^^^^^^^^^
  File "/opt/airflow/dags/stock_etl_dag.py", line 92, in load_data
    conn.execute(text(f"""
  File "/home/airflow/.local/lib/python3.12/site-packages/sqlalchemy/engine/base.py", line 1385, in execute
    return meth(self, multiparams, params, _EMPTY_EXECUTION_OPTS)
           ^^^^^^^^^^^^^^^^^^^^^^^^^^^^^^^^^^^^^^^^^^^^^^^^^^^^^^
  File "/home/airflow/.local/lib/python3.12/site-packages/sqlalchemy/sql/elements.py", line 334, in _execute_on_connection
    return connection._execute_clauseelement(
           ^^^^^^^^^^^^^^^^^^^^^^^^^^^^^^^^^^
  File "/home/airflow/.local/lib/python3.12/site-packages/sqlalchemy/engine/base.py", line 1577, in _execute_clauseelement
    ret = self._execute_context(
          ^^^^^^^^^^^^^^^^^^^^^^
  File "/home/airflow/.local/lib/python3.12/site-packages/sqlalchemy/engine/base.py", line 1953, in _execute_context
    self._handle_dbapi_exception(
  File "/home/airflow/.local/lib/python3.12/site-packages/sqlalchemy/engine/base.py", line 2134, in _handle_dbapi_exception
    util.raise_(
  File "/home/airflow/.local/lib/python3.12/site-packages/sqlalchemy/util/compat.py", line 211, in raise_
    raise exception
  File "/home/airflow/.local/lib/python3.12/site-packages/sqlalchemy/engine/base.py", line 1910, in _execute_context
    self.dialect.do_execute(
  File "/home/airflow/.local/lib/python3.12/site-packages/sqlalchemy/engine/default.py", line 736, in do_execute
    cursor.execute(statement, parameters)
sqlalchemy.exc.ProgrammingError: (psycopg2.errors.UndefinedColumn) column t.ticker does not exist
LINE 3:             SELECT t.ticker, t.timestamp, t.open, t.high, t....
                           ^

[SQL: 
            INSERT INTO stock_data (ticker, timestamp, open, high, low, close, volume)
            SELECT t.ticker, t.timestamp, t.open, t.high, t.low, t.close, t.volume
            FROM temp_stock_data AS t
            ON CONFLICT (ticker, timestamp) DO NOTHING;
        ]
(Background on this error at: https://sqlalche.me/e/14/f405)
[2025-10-21T01:17:39.294+0300] {taskinstance.py:1206} INFO - Marking task as UP_FOR_RETRY. dag_id=stock_etl, task_id=load_task, run_id=manual__2025-10-20T22:07:02.645204+00:00, execution_date=20251020T220702, start_date=20251020T221651, end_date=20251020T221739
[2025-10-21T01:17:40.773+0300] {standard_task_runner.py:110} ERROR - Failed to execute job 118 for task load_task ((psycopg2.errors.UndefinedColumn) column t.ticker does not exist
LINE 3:             SELECT t.ticker, t.timestamp, t.open, t.high, t....
                           ^

[SQL: 
            INSERT INTO stock_data (ticker, timestamp, open, high, low, close, volume)
            SELECT t.ticker, t.timestamp, t.open, t.high, t.low, t.close, t.volume
            FROM temp_stock_data AS t
            ON CONFLICT (ticker, timestamp) DO NOTHING;
        ]
(Background on this error at: https://sqlalche.me/e/14/f405); 328)
[2025-10-21T01:17:40.798+0300] {local_task_job_runner.py:243} INFO - Task exited with return code 1
[2025-10-21T01:17:43.563+0300] {local_task_job_runner.py:222} INFO - ::endgroup::
